Workbook
Name AccountingTypes: OFFSET('Accounting & Mapping Type'!$A$2,0,0,COUNTA('Accounting & Mapping Type'!$A$2:$A$200),1)
Name BudgetCodes_All: OFFSET('Accounting & Mapping Type'!$I$2,0,0,COUNTA('Accounting & Mapping Type'!$I$2:$I$200),1)
Name BudgetCodes_Neg: OFFSET('Accounting & Mapping Type'!$I$2,COUNTIF('Accounting & Mapping Type'!$I$2:$I$200,"+*"),0,COUNTIF('Accounting & Mapping Type'!$I$2:$I$200,"-*"),1)
Name BudgetCodes_Pos: OFFSET('Accounting & Mapping Type'!$I$2,0,0,COUNTIF('Accounting & Mapping Type'!$I$2:$I$200,"+*"),1)

Sheet Accounting & Mapping Type
A1: Accounting Type | B1: Mapping Table | D1: FCM | E1: BS | I1: Budget Code | J1: Flow Code | K1: +BAL | N1: Co Code | O1: Profit Center | P1: Profit Center Name | T1: Kyriba Account Code | U1: GL Account Number | V1: Incoming GL Account | W1: Outgoing GL Account
A2: +BAL_MODCF | B2: +BAL_MODCF | D2: SB | E2: SH | I2: +CAP_CON | J2: +ACH | K2: +BAL | N2: 1000 | O2: INC00 | P2: OTHER INCOME | T2: 1000CITUS498 | U2: 1202680010 | V2: 1202690011 | W2: 1202690012
A3: 2-Line BTB Bank | B3: CA_BANK | D3: SC | E3: AL | I3: +DIV_IN | J3: +FX | K3: +BAL | N3: 1000 | O3: INV00 | P3: INVESTMENT INCOME | T3: 1000JPMUS222 | U3: 1202681110 | V3: 1202691111 | W3: 1202691112
A4: 2-Line BTB Offset | B4: CA_OFFSET | D4: KT | E4: VC | I4: +EFT_IN | J4: +WIRE | K4: +BAL | N4: 1840 | O4: INC03 | P4: OTHER INCOME - CM | T4: 1000JPMUS231 | U4: 1202681300 | V4: 1202691301 | W4: 1202691302
A5: 4-Line BTB Bank | D5: ST | E5: RS | I5: +FX_IN | J5: +WIRE_FP | K5: +BAL | N5: 1840 | O5: INV03 | P5: INVESTMENT INCOME - CM | T5: 1000JPMUS734 | U5: 1202680550 | V5: 1202690551 | W5: 1202690552
A6: 4-Line BTB Offset | E6: MW | I6: +NONOP_I | J6: -ACH | K6: +BAL | N6: 2200 | O6: INC01 | P6: OTHER INCOME - INDVB | T6: 1000JPMUS742 | U6: 1202680620 | V6: 1202690621 | W6: 1202690622
A7: External | I7: +OP_DEP | J7: -FX | K7: +BAL | N7: 2200 | O7: INV01 | P7: INVESTMENT INCOME - INDVB | T7: 1000JPMUS759 | U7: 1202680590 | V7: 1202690591 | W7: 1202690592
A8: Receipts | I8: +PLADS_I | J8: -WIRE | K8: +BAL | N8: 2400 | O8: INC01 | P8: OTHER INCOME - INDVB | T8: 1000JPMUS767 | U8: 1202680610 | V8: 1202690611 | W8: 1202690612
I9: +REINSUR | J9: -WIRE_FP | K9: +BAL | N9: 2400 | O9: INV01 | P9: INVESTMENT INCOME - INDVB | T9: 1000JPMUS269 | U9: 1202680530 | V9: 1202690531 | W9: 1202690532
I10: +SA_IN | K10: +BAL | N10: 2500 | O10: INC02 | P10: OTHER INCOME - GRPVB | T10: 1000JPMUS775 | U10: 1202680600 | V10: 1202690601 | W10: 1202690602
I11: +STI_IN | K11: +BAL | N11: 2500 | O11: INV02 | P11: INVESTMENT INCOME - GRPVB | T11: 1000MUFJP902 | U11: 1202680920 | V11: 1202690921 | W11: 1202690922
I12: +TAXES | K12: +BAL | N12: 2560 | O12: INC05 | P12: OTHER INCOME - CTPFML | T12: 1000MUFUS505 | U12: 1202680940 | V12: 1202690941 | W12: 1202690942
I13: -CAP_CON | K13: +BAL | N13: 2600 | O13: INC03 | P13: OTHER INCOME - CM | T13: 1000PNCUS489 | U13: 1202681410 | V13: 1202691411 | W13: 1202691412
I14: -DIV_OUT | K14: +BAL | N14: 2600 | O14: INV03 | P14: INVESTMENT INCOME - CM | T14: 1000PNCUS701 | U14: 1202682120 | V14: 1202692121 | W14: 1202692122
I15: -EFT_OUT | K15: +BAL | N15: 2810 | O15: INV06 | P15: INVESTMENT INCOME - D&V | T15: 1012JPMUS855 | U15: 1202680550 | V15: 1202690551 | W15: 1202690552
I16: -FX_OUT | K16: +BAL | T16: 1012JPMUS900 | U16: 1202680530 | V16: 1202690531 | W16: 1202690532
I17: -NONOP_O | K17: +BAL | T17: 1100JPMUS783 | U17: 1202680550 | V17: 1202690551 | W17: 1202690552
I18: -OP_EXP | K18: +BAL | T18: 1100JPMUS791 | U18: 1202680620 | V18: 1202690621 | W18: 1202690622
I19: -PLADS_O | K19: +BAL | T19: 1100JPMUS999 | U19: 1202681300 | V19: 1202691301 | W19: 1202691302
I20: -REINSUR | K20: +BAL | T20: 1200JPMUS621 | U20: 1202681300 | V20: 1202691301 | W20: 1202691302
I21: -SA_OUT | K21: +BAL | T21: 1200JPMUS627 | U21: 1202680530 | V21: 1202690531 | W21: 1202690532
I22: -STI_OUT | K22: +BAL | T22: 1200JPMUS635 | U22: 1202680550 | V22: 1202690551 | W22: 1202690552
I23: -TAXES | K23: +BAL | T23: 1200JPMUS650 | U23: 1202680620 | V23: 1202690621 | W23: 1202690622
K24: +BAL | T24: 1400JPMUS809 | U24: 1202680550 | V24: 1202690551 | W24: 1202690552
K25: +BAL | T25: 1500JPMUS249 | U25: 1202680130 | V25: 1202690131 | W25: 1202690132
K26: +BAL | T26: 1500JPMUS737 | U26: 1202680660 | V26: 1202690661 | W26: 1202690662
K27: +BAL | T27: 1600PNCUS041 | U27: 1202681460 | V27: 1202691461 | W27: 1202691462
K28: +BAL | T28: 1600JPMUS793 | U28: 1202680530 | V28: 1202690531 | W28: 1202690532
K29: +BAL | T29: 1600JPMUS801 | U29: 1202680550 | V29: 1202690551 | W29: 1202690552
K30: +BAL | T30: 1800BOAUS544 | U30: 1202680510 | V30: 1202690511 | W30: 1202690512
K31: +BAL | T31: 1800BOAUS790 | U31: 1202680240 | V31: 1202690241 | W31: 1202690242
K32: +BAL | T32: 1800MUFJP102 | U32: 1202680920 | V32: 1202690921 | W32: 1202690922
K33: +BAL | T33: 1800JPMUS271 | U33: 1202680550 | V33: 1202690551 | W33: 1202690552
K34: +BAL | T34: 1800JPMUS263 | U34: 1202680530 | V34: 1202690531 | W34: 1202690532
K35: +BAL | T35: 1810BOAUS800 | U35: 1202680240 | V35: 1202690241 | W35: 1202690242
... K50: +BAL | T50: 2200BOAUS340 | U50: 1202680240 | V50: 1202690241 | W50: 1202690242
K51: +BAL | T51: 2200BOAUS962 | U51: 1201010021
K52: +BAL | T52: 2200CITUS247 | U52: 1202681580 | V52: 1202691581 | W52: 1202691582
K53: +BAL | T53: 2200CITUS255 | U53: 1202681600 | V53: 1202691601 | W53: 1202691602
K54: +BAL | T54: 2200CITUS298 | U54: 1202682010 | V54: 1202692011 | W54: 1202692012
...

Sheet Requirements
A1: Accounting Type | B1: Number of Rows | C1: +BAL_MODCF | D1: 2-Line BTB CA_BANK | E1: 2-Line BTB CA_OFFSET | F1: 2-Line BTB CA_BANK | G1: 2-Line BTB CA_OFFSET | H1: 4-Line BTB CA_BANK | I1: 4-Line BTB CA_OFFSET | J1: 4-Line BTB CA_BANK | K1: 4-Line BTB CA_OFFSET | L1: External Transfer CA_BANK | M1: External CA_OFFSET | N1: Receipts CA_BANK | O1: Receipts CA_OFFSET
A2: +BAL_MODCF | B2: 1 | C2: +BAL_MODCF | D2: CA_BANK | E2: CA_OFFSET | F2: CA_BANK | G2: CA_OFFSET | H2: CA_BANK | I2: CA_OFFSET | J2: CA_BANK | K2: CA_OFFSET | L2: CA_BANK | M2: CA_OFFSET | N2: CA_BANK | O2: CA_BANK
A3: 2-Line BTB CA_BANK | B3: 2 | C3: PET Code or Description | D3: Bank Statement Cash Flow Direction | E3: Bank Statement Cash Flow Direction | F3: Bank Statement Cash Flow Direction | G3: Bank Statement Cash Flow Direction | H3: Bank Statement Cash Flow Direction | I3: Bank Statement Cash Flow Direction | J3: Bank Statement Cash Flow Direction | K3: Bank Statement Cash Flow Direction | L3: Account Code | M3: Account Code | N3: Account Code | O3: Account Code
A4: 2-Line BTB CA_OFFSET | B4: 2 | C4: Offset Budget Code | D4: Account Code | E4: Account Code | F4: Account Code | G4: Account Code | H4: Account Code | I4: Account Code | J4: Account Code | K4: Account Code | L4: PET Code or Description | M4: PET Code or Description | N4: Flow Code | O4: Flow Code
A5: 4-Line BTB CA_BANK | B5: 2 | C5: Flow Code | D5: PET Code or Description | E5: PET Code or Description | F5: PET Code or Description | G5: PET Code or Description | H5: PET Code or Description | I5: PET Code or Description | J5: PET Code or Description | K5: PET Code or Description | L5: Long Text | M5: Long Text | N5: Budget Code | O5: Budget Code
A6: 4-Line BTB CA_OFFSET | B6: 2 | D6: Description 2 | E6: Long Text | F6: Description 2 | G6: Long Text | H6: Description 2 | I6: Long Text | J6: Description 2 | K6: Long Text | L6: Bank GL account | M6: GL account | N6: Description | O6: Description
A7: 4-Line BTB | B7: 4 | D7: Description 3 | E7: GL account (DNP) | F7: Description 3 | G7: GL account (DNP) | H7: Description 3 | I7: GL account | J7: Description 3 | K7: GL account | M7: Cost center | N7: Description 2 | O7: Description 2
A8: External Transfer CA_BANK | B8: 1 | D8: Long Text | F8: Long Text | H8: Long Text | I8: Cost center | J8: Long Text | K8: Cost center | M8: Profit center | N8: Description 3 | O8: Description 3
A9: External Transfer CA_OFFSET | B9: 1 | D9: Bank GL account | F9: Bank GL account | H9: Budget Code | I9: Profit center | J9: Budget Code | K9: Profit center | M9: Trading partner | N9: Long Text | O9: Long Text
A10: Receipts CA_BANK | B10: 1 | H10: Bank GL account | I10: Trading partner | J10: Bank GL account | K10: Trading partner | N10: Bank GL account | O10: GL account
A11: Receipts CA_OFFSET | B11: 1 | O11: Cost center
O12: Profit center
O13: Trading partner

Sheet FCM Input
C1: Copy and Paste as Values in Cooresponding Row, Column C on 'BS Rule Values' Tab | J1: As Needed | L1: DNP for 2-Line BTB Offset | N1: N/A for Bank GL Accounts | Q1: As Needed
A2: Entered By | B2: Entered Date | C2: Rule for Banking Services | D2: Accounting Type | E2: Flow Code | F2: PET Budget Code | G2: PET Code or Description | H2: Offset Budget Code | I2: DEBIT Account Code (Outgoing) | J2: Receiving Account Code (Incoming) | K2: Paying GL Account (Outgoing) | L2: Receiving GL Account (Incoming) | M2: Long Text | N2: Cost center | O2: Profit center | P2: Trading partner | Q2: Description 2 | R2: Description 3
A3: ST | B3: 46288 | D3: +BAL_MODCF | E3: +BAL | F3: +CAP_CON | H3: -CAP_CON | I3: =IF($D3="2-Line BTB Offset","N/A","") | J3: =IF($D3="2-Line BTB Bank","N/A","") | K3: =IF($I3="N/A","DNP",IF($I3="","",IFERROR(IF(LEN(INDEX('Accounting & Mapping Type'!$W$2:$W$5000,MATCH($I3,'Accounting & Mapping Type'!$T$2:$T$5000,0)))>0,INDEX('Accounting & Mapping Type'!$W$2:$W$5000,MATCH($I3,'Accounting & Mapping Type'!$T$2:$T$5000,0)),IF(LEN(INDEX('Accounting & Mapping Type'!$U$2:$U$5000,MATCH($I3,'Accounting & Mapping Type'!$T$2:$T$5000,0)))>0,INDEX('Accounting & Mapping Type'!$U$2:$U$5000,MATCH($I3,'Accounting & Mapping Type'!$T$2:$T$5000,0)),"")),""))) | L3: =IF($J3="N/A","DNP",IF($J3="","",IFERROR(IF(LEN(INDEX('Accounting & Mapping Type'!$V$2:$V$5000,MATCH($J3,'Accounting & Mapping Type'!$T$2:$T$5000,0)))>0,INDEX('Accounting & Mapping Type'!$V$2:$V$5000,MATCH($J3,'Accounting & Mapping Type'!$T$2:$T$5000,0)),IF(LEN(INDEX('Accounting & Mapping Type'!$U$2:$U$5000,MATCH($J3,'Accounting & Mapping Type'!$T$2:$T$5000,0)))>0,INDEX('Accounting & Mapping Type'!$U$2:$U$5000,MATCH($J3,'Accounting & Mapping Type'!$T$2:$T$5000,0)),"")),"")))
C4: rule is same on both bank & offset. Only change is accounting | D4: 2-Line BTB Bank | E4: +ACH | F4: +DIV_IN | H4: -EFT_OUT | I4: =IF($D4="2-Line BTB Offset","N/A","") | J4: =IF($D4="2-Line BTB Bank","N/A","") -> N/A | K4: =IF($I4="N/A","DNP",IF($I4="","",IFERROR(IF(LEN(INDEX('Accounting & Mapping Type'!$W$2:$W$5000,MATCH($I4,'Accounting & Mapping Type'!$T$2:$T$5000,0)))>0,INDEX('Accounting & Mapping Type'!$W$2:$W$5000,MATCH($I4,'Accounting & Mapping Type'!$T$2:$T$5000,0)),IF(LEN(INDEX('Accounting & Mapping Type'!$U$2:$U$5000,MATCH($I4,'Accounting & Mapping Type'!$T$2:$T$5000,0)))>0,INDEX('Accounting & Mapping Type'!$U$2:$U$5000,MATCH($I4,'Accounting & Mapping Type'!$T$2:$T$5000,0)),"")),""))) | L4: =IF($J4="N/A","DNP",IF($J4="","",IFERROR(IF(LEN(INDEX('Accounting & Mapping Type'!$V$2:$V$5000,MATCH($J4,'Accounting & Mapping Type'!$T$2:$T$5000,0)))>0,INDEX('Accounting & Mapping Type'!$V$2:$V$5000,MATCH($J4,'Accounting & Mapping Type'!$T$2:$T$5000,0)),IF(LEN(INDEX('Accounting & Mapping Type'!$U$2:$U$5000,MATCH($J4,'Accounting & Mapping Type'!$T$2:$T$5000,0)))>0,INDEX('Accounting & Mapping Type'!$U$2:$U$5000,MATCH($J4,'Accounting & Mapping Type'!$T$2:$T$5000,0)),"")),""))) -> DNP
D5: 2-Line BTB Offset | E5: +FX | F5: +FX_IN | H5: -SA_OUT | I5: =IF($D5="2-Line BTB Offset","N/A","") -> N/A | J5: =IF($D5="2-Line BTB Bank","N/A","") | K5: =IF($I5="N/A","DNP",IF($I5="","",IFERROR(IF(LEN(INDEX('Accounting & Mapping Type'!$W$2:$W$5000,MATCH($I5,'Accounting & Mapping Type'!$T$2:$T$5000,0)))>0,INDEX('Accounting & Mapping Type'!$W$2:$W$5000,MATCH($I5,'Accounting & Mapping Type'!$T$2:$T$5000,0)),IF(LEN(INDEX('Accounting & Mapping Type'!$U$2:$U$5000,MATCH($I5,'Accounting & Mapping Type'!$T$2:$T$5000,0)))>0,INDEX('Accounting & Mapping Type'!$U$2:$U$5000,MATCH($I5,'Accounting & Mapping Type'!$T$2:$T$5000,0)),"")),""))) -> DNP | L5: =IF($J5="N/A","DNP",IF($J5="","",IFERROR(IF(LEN(INDEX('Accounting & Mapping Type'!$V$2:$V$5000,MATCH($J5,'Accounting & Mapping Type'!$T$2:$T$5000,0)))>0,INDEX('Accounting & Mapping Type'!$V$2:$V$5000,MATCH($J5,'Accounting & Mapping Type'!$T$2:$T$5000,0)),IF(LEN(INDEX('Accounting & Mapping Type'!$U$2:$U$5000,MATCH($J5,'Accounting & Mapping Type'!$T$2:$T$5000,0)))>0,INDEX('Accounting & Mapping Type'!$U$2:$U$5000,MATCH($J5,'Accounting & Mapping Type'!$T$2:$T$5000,0)),"")),"")))
D6: 4-Line BTB Bank | E6: +WIRE | F6: +REINSUR | H6: -EFT_OUT | I6: =IF($D6="2-Line BTB Offset","N/A","") | J6: =IF($D6="2-Line BTB Bank","N/A","") | K6: =IF($I6="N/A","DNP",IF($I6="","",IFERROR(IF(LEN(INDEX('Accounting & Mapping Type'!$W$2:$W$5000,MATCH($I6,'Accounting & Mapping Type'!$T$2:$T$5000,0)))>0,INDEX('Accounting & Mapping Type'!$W$2:$W$5000,MATCH($I6,'Accounting & Mapping Type'!$T$2:$T$5000,0)),IF(LEN(INDEX('Accounting & Mapping Type'!$U$2:$U$5000,MATCH($I6,'Accounting & Mapping Type'!$T$2:$T$5000,0)))>0,INDEX('Accounting & Mapping Type'!$U$2:$U$5000,MATCH($I6,'Accounting & Mapping Type'!$T$2:$T$5000,0)),"")),""))) | L6: =IF($J6="N/A","DNP",IF($J6="","",IFERROR(IF(LEN(INDEX('Accounting & Mapping Type'!$V$2:$V$5000,MATCH($J6,'Accounting & Mapping Type'!$T$2:$T$5000,0)))>0,INDEX('Accounting & Mapping Type'!$V$2:$V$5000,MATCH($J6,'Accounting & Mapping Type'!$T$2:$T$5000,0)),IF(LEN(INDEX('Accounting & Mapping Type'!$U$2:$U$5000,MATCH($J6,'Accounting & Mapping Type'!$T$2:$T$5000,0)))>0,INDEX('Accounting & Mapping Type'!$U$2:$U$5000,MATCH($J6,'Accounting & Mapping Type'!$T$2:$T$5000,0)),"")),"")))
D7: 4-Line BTB Offset | E7: +WIRE_FP | F7: +SA_IN | H7: -FX_OUT | I7: =IF($D7="2-Line BTB Offset","N/A","") | J7: =IF($D7="2-Line BTB Bank","N/A","") | K7: =IF($I7="N/A","DNP",IF($I7="","",IFERROR(IF(LEN(INDEX('Accounting & Mapping Type'!$W$2:$W$5000,MATCH($I7,'Accounting & Mapping Type'!$T$2:$T$5000,0)))>0,INDEX('Accounting & Mapping Type'!$W$2:$W$5000,MATCH($I7,'Accounting & Mapping Type'!$T$2:$T$5000,0)),IF(LEN(INDEX('Accounting & Mapping Type'!$U$2:$U$5000,MATCH($I7,'Accounting & Mapping Type'!$T$2:$T$5000,0)))>0,INDEX('Accounting & Mapping Type'!$U$2:$U$5000,MATCH($I7,'Accounting & Mapping Type'!$T$2:$T$5000,0)),"")),""))) | L7: =IF($J7="N/A","DNP",IF($J7="","",IFERROR(IF(LEN(INDEX('Accounting & Mapping Type'!$V$2:$V$5000,MATCH($J7,'Accounting & Mapping Type'!$T$2:$T$5000,0)))>0,INDEX('Accounting & Mapping Type'!$V$2:$V$5000,MATCH($J7,'Accounting & Mapping Type'!$T$2:$T$5000,0)),IF(LEN(INDEX('Accounting & Mapping Type'!$U$2:$U$5000,MATCH($J7,'Accounting & Mapping Type'!$T$2:$T$5000,0)))>0,INDEX('Accounting & Mapping Type'!$U$2:$U$5000,MATCH($J7,'Accounting & Mapping Type'!$T$2:$T$5000,0)),"")),"")))
C8: rule is same on both bank & offset. Only change is accounting | D8: External | E8: -WIRE | F8: +FX_IN | H8: -CAP_CON | I8: =IF($D8="2-Line BTB Offset","N/A","") | J8: =IF($D8="2-Line BTB Bank","N/A","") | K8: =IF($I8="N/A","DNP",IF($I8="","",IFERROR(IF(LEN(INDEX('Accounting & Mapping Type'!$W$2:$W$5000,MATCH($I8,'Accounting & Mapping Type'!$T$2:$T$5000,0)))>0,INDEX('Accounting & Mapping Type'!$W$2:$W$5000,MATCH($I8,'Accounting & Mapping Type'!$T$2:$T$5000,0)),IF(LEN(INDEX('Accounting & Mapping Type'!$U$2:$U$5000,MATCH($I8,'Accounting & Mapping Type'!$T$2:$T$5000,0)))>0,INDEX('Accounting & Mapping Type'!$U$2:$U$5000,MATCH($I8,'Accounting & Mapping Type'!$T$2:$T$5000,0)),"")),""))) | L8: =IF($J8="N/A","DNP",IF($J8="","",IFERROR(IF(LEN(INDEX('Accounting & Mapping Type'!$V$2:$V$5000,MATCH($J8,'Accounting & Mapping Type'!$T$2:$T$5000,0)))>0,INDEX('Accounting & Mapping Type'!$V$2:$V$5000,MATCH($J8,'Accounting & Mapping Type'!$T$2:$T$5000,0)),IF(LEN(INDEX('Accounting & Mapping Type'!$U$2:$U$5000,MATCH($J8,'Accounting & Mapping Type'!$T$2:$T$5000,0)))>0,INDEX('Accounting & Mapping Type'!$U$2:$U$5000,MATCH($J8,'Accounting & Mapping Type'!$T$2:$T$5000,0)),"")),"")))
D9: Receipts | E9: -WIRE_FP | F9: -CAP_CON | H9: +NONOP_I | I9: =IF($D9="2-Line BTB Offset","N/A","") | J9: =IF($D9="2-Line BTB Bank","N/A","") | K9: =IF($I9="N/A","DNP",IF($I9="","",IFERROR(IF(LEN(INDEX('Accounting & Mapping Type'!$W$2:$W$5000,MATCH($I9,'Accounting & Mapping Type'!$T$2:$T$5000,0)))>0,INDEX('Accounting & Mapping Type'!$W$2:$W$5000,MATCH($I9,'Accounting & Mapping Type'!$T$2:$T$5000,0)),IF(LEN(INDEX('Accounting & Mapping Type'!$U$2:$U$5000,MATCH($I9,'Accounting & Mapping Type'!$T$2:$T$5000,0)))>0,INDEX('Accounting & Mapping Type'!$U$2:$U$5000,MATCH($I9,'Accounting & Mapping Type'!$T$2:$T$5000,0)),"")),""))) | L9: =IF($J9="N/A","DNP",IF($J9="","",IFERROR(IF(LEN(INDEX('Accounting & Mapping Type'!$V$2:$V$5000,MATCH($J9,'Accounting & Mapping Type'!$T$2:$T$5000,0)))>0,INDEX('Accounting & Mapping Type'!$V$2:$V$5000,MATCH($J9,'Accounting & Mapping Type'!$T$2:$T$5000,0)),IF(LEN(INDEX('Accounting & Mapping Type'!$U$2:$U$5000,MATCH($J9,'Accounting & Mapping Type'!$T$2:$T$5000,0)))>0,INDEX('Accounting & Mapping Type'!$U$2:$U$5000,MATCH($J9,'Accounting & Mapping Type'!$T$2:$T$5000,0)),"")),"")))
I10: =IF($D10="2-Line BTB Offset","N/A","") | J10: =IF($D10="2-Line BTB Bank","N/A","") | K10: =IF($I10="N/A","DNP",IF($I10="","",IFERROR(IF(LEN(INDEX('Accounting & Mapping Type'!$W$2:$W$5000,MATCH($I10,'Accounting & Mapping Type'!$T$2:$T$5000,0)))>0,INDEX('Accounting & Mapping Type'!$W$2:$W$5000,MATCH($I10,'Accounting & Mapping Type'!$T$2:$T$5000,0)),IF(LEN(INDEX('Accounting & Mapping Type'!$U$2:$U$5000,MATCH($I10,'Accounting & Mapping Type'!$T$2:$T$5000,0)))>0,INDEX('Accounting & Mapping Type'!$U$2:$U$5000,MATCH($I10,'Accounting & Mapping Type'!$T$2:$T$5000,0)),"")),""))) | L10: =IF($J10="N/A","DNP",IF($J10="","",IFERROR(IF(LEN(INDEX('Accounting & Mapping Type'!$V$2:$V$5000,MATCH($J10,'Accounting & Mapping Type'!$T$2:$T$5000,0)))>0,INDEX('Accounting & Mapping Type'!$V$2:$V$5000,MATCH($J10,'Accounting & Mapping Type'!$T$2:$T$5000,0)),IF(LEN(INDEX('Accounting & Mapping Type'!$U$2:$U$5000,MATCH($J10,'Accounting & Mapping Type'!$T$2:$T$5000,0)))>0,INDEX('Accounting & Mapping Type'!$U$2:$U$5000,MATCH($J10,'Accounting & Mapping Type'!$T$2:$T$5000,0)),"")),"")))
I11: =IF($D11="2-Line BTB Offset","N/A","") | J11: =IF($D11="2-Line BTB Bank","N/A","") | K11: =IF($I11="N/A","DNP",IF($I11="","",IFERROR(IF(LEN(INDEX('Accounting & Mapping Type'!$W$2:$W$5000,MATCH($I11,'Accounting & Mapping Type'!$T$2:$T$5000,0)))>0,INDEX('Accounting & Mapping Type'!$W$2:$W$5000,MATCH($I11,'Accounting & Mapping Type'!$T$2:$T$5000,0)),IF(LEN(INDEX('Accounting & Mapping Type'!$U$2:$U$5000,MATCH($I11,'Accounting & Mapping Type'!$T$2:$T$5000,0)))>0,INDEX('Accounting & Mapping Type'!$U$2:$U$5000,MATCH($I11,'Accounting & Mapping Type'!$T$2:$T$5000,0)),"")),""))) | L11: =IF($J11="N/A","DNP",IF($J11="","",IFERROR(IF(LEN(INDEX('Accounting & Mapping Type'!$V$2:$V$5000,MATCH($J11,'Accounting & Mapping Type'!$T$2:$T$5000,0)))>0,INDEX('Accounting & Mapping Type'!$V$2:$V$5000,MATCH($J11,'Accounting & Mapping Type'!$T$2:$T$5000,0)),IF(LEN(INDEX('Accounting & Mapping Type'!$U$2:$U$5000,MATCH($J11,'Accounting & Mapping Type'!$T$2:$T$5000,0)))>0,INDEX('Accounting & Mapping Type'!$U$2:$U$5000,MATCH($J11,'Accounting & Mapping Type'!$T$2:$T$5000,0)),"")),"")))
I12: =IF($D12="2-Line BTB Offset","N/A","") | J12: =IF($D12="2-Line BTB Bank","N/A","") | K12: =IF($I12="N/A","DNP",IF($I12="","",IFERROR(IF(LEN(INDEX('Accounting & Mapping Type'!$W$2:$W$5000,MATCH($I12,'Accounting & Mapping Type'!$T$2:$T$5000,0)))>0,INDEX('Accounting & Mapping Type'!$W$2:$W$5000,MATCH($I12,'Accounting & Mapping Type'!$T$2:$T$5000,0)),IF(LEN(INDEX('Accounting & Mapping Type'!$U$2:$U$5000,MATCH($I12,'Accounting & Mapping Type'!$T$2:$T$5000,0)))>0,INDEX('Accounting & Mapping Type'!$U$2:$U$5000,MATCH($I12,'Accounting & Mapping Type'!$T$2:$T$5000,0)),"")),""))) | L12: =IF($J12="N/A","DNP",IF($J12="","",IFERROR(IF(LEN(INDEX('Accounting & Mapping Type'!$V$2:$V$5000,MATCH($J12,'Accounting & Mapping Type'!$T$2:$T$5000,0)))>0,INDEX('Accounting & Mapping Type'!$V$2:$V$5000,MATCH($J12,'Accounting & Mapping Type'!$T$2:$T$5000,0)),IF(LEN(INDEX('Accounting & Mapping Type'!$U$2:$U$5000,MATCH($J12,'Accounting & Mapping Type'!$T$2:$T$5000,0)))>0,INDEX('Accounting & Mapping Type'!$U$2:$U$5000,MATCH($J12,'Accounting & Mapping Type'!$T$2:$T$5000,0)),"")),"")))
I13: =IF($D13="2-Line BTB Offset","N/A","") | J13: =IF($D13="2-Line BTB Bank","N/A","") | K13: =IF($I13="N/A","DNP",IF($I13="","",IFERROR(IF(LEN(INDEX('Accounting & Mapping Type'!$W$2:$W$5000,MATCH($I13,'Accounting & Mapping Type'!$T$2:$T$5000,0)))>0,INDEX('Accounting & Mapping Type'!$W$2:$W$5000,MATCH($I13,'Accounting & Mapping Type'!$T$2:$T$5000,0)),IF(LEN(INDEX('Accounting & Mapping Type'!$U$2:$U$5000,MATCH($I13,'Accounting & Mapping Type'!$T$2:$T$5000,0)))>0,INDEX('Accounting & Mapping Type'!$U$2:$U$5000,MATCH($I13,'Accounting & Mapping Type'!$T$2:$T$5000,0)),"")),""))) | L13: =IF($J13="N/A","DNP",IF($J13="","",IFERROR(IF(LEN(INDEX('Accounting & Mapping Type'!$V$2:$V$5000,MATCH($J13,'Accounting & Mapping Type'!$T$2:$T$5000,0)))>0,INDEX('Accounting & Mapping Type'!$V$2:$V$5000,MATCH($J13,'Accounting & Mapping Type'!$T$2:$T$5000,0)),IF(LEN(INDEX('Accounting & Mapping Type'!$U$2:$U$5000,MATCH($J13,'Accounting & Mapping Type'!$T$2:$T$5000,0)))>0,INDEX('Accounting & Mapping Type'!$U$2:$U$5000,MATCH($J13,'Accounting & Mapping Type'!$T$2:$T$5000,0)),"")),"")))
I14: =IF($D14="2-Line BTB Offset","N/A","") | J14: =IF($D14="2-Line BTB Bank","N/A","") | K14: =IF($I14="N/A","DNP",IF($I14="","",IFERROR(IF(LEN(INDEX('Accounting & Mapping Type'!$W$2:$W$5000,MATCH($I14,'Accounting & Mapping Type'!$T$2:$T$5000,0)))>0,INDEX('Accounting & Mapping Type'!$W$2:$W$5000,MATCH($I14,'Accounting & Mapping Type'!$T$2:$T$5000,0)),IF(LEN(INDEX('Accounting & Mapping Type'!$U$2:$U$5000,MATCH($I14,'Accounting & Mapping Type'!$T$2:$T$5000,0)))>0,INDEX('Accounting & Mapping Type'!$U$2:$U$5000,MATCH($I14,'Accounting & Mapping Type'!$T$2:$T$5000,0)),"")),""))) | L14: =IF($J14="N/A","DNP",IF($J14="","",IFERROR(IF(LEN(INDEX('Accounting & Mapping Type'!$V$2:$V$5000,MATCH($J14,'Accounting & Mapping Type'!$T$2:$T$5000,0)))>0,INDEX('Accounting & Mapping Type'!$V$2:$V$5000,MATCH($J14,'Accounting & Mapping Type'!$T$2:$T$5000,0)),IF(LEN(INDEX('Accounting & Mapping Type'!$U$2:$U$5000,MATCH($J14,'Accounting & Mapping Type'!$T$2:$T$5000,0)))>0,INDEX('Accounting & Mapping Type'!$U$2:$U$5000,MATCH($J14,'Accounting & Mapping Type'!$T$2:$T$5000,0)),"")),"")))
I15: =IF($D15="2-Line BTB Offset","N/A","") | J15: =IF($D15="2-Line BTB Bank","N/A","") | K15: =IF($I15="N/A","DNP",IF($I15="","",IFERROR(IF(LEN(INDEX('Accounting & Mapping Type'!$W$2:$W$5000,MATCH($I15,'Accounting & Mapping Type'!$T$2:$T$5000,0)))>0,INDEX('Accounting & Mapping Type'!$W$2:$W$5000,MATCH($I15,'Accounting & Mapping Type'!$T$2:$T$5000,0)),IF(LEN(INDEX('Accounting & Mapping Type'!$U$2:$U$5000,MATCH($I15,'Accounting & Mapping Type'!$T$2:$T$5000,0)))>0,INDEX('Accounting & Mapping Type'!$U$2:$U$5000,MATCH($I15,'Accounting & Mapping Type'!$T$2:$T$5000,0)),"")),""))) | L15: =IF($J15="N/A","DNP",IF($J15="","",IFERROR(IF(LEN(INDEX('Accounting & Mapping Type'!$V$2:$V$5000,MATCH($J15,'Accounting & Mapping Type'!$T$2:$T$5000,0)))>0,INDEX('Accounting & Mapping Type'!$V$2:$V$5000,MATCH($J15,'Accounting & Mapping Type'!$T$2:$T$5000,0)),IF(LEN(INDEX('Accounting & Mapping Type'!$U$2:$U$5000,MATCH($J15,'Accounting & Mapping Type'!$T$2:$T$5000,0)))>0,INDEX('Accounting & Mapping Type'!$U$2:$U$5000,MATCH($J15,'Accounting & Mapping Type'!$T$2:$T$5000,0)),"")),"")))
I16: =IF($D16="2-Line BTB Offset","N/A","") | J16: =IF($D16="2-Line BTB Bank","N/A","") | K16: =IF($I16="N/A","DNP",IF($I16="","",IFERROR(IF(LEN(INDEX('Accounting & Mapping Type'!$W$2:$W$5000,MATCH($I16,'Accounting & Mapping Type'!$T$2:$T$5000,0)))>0,INDEX('Accounting & Mapping Type'!$W$2:$W$5000,MATCH($I16,'Accounting & Mapping Type'!$T$2:$T$5000,0)),IF(LEN(INDEX('Accounting & Mapping Type'!$U$2:$U$5000,MATCH($I16,'Accounting & Mapping Type'!$T$2:$T$5000,0)))>0,INDEX('Accounting & Mapping Type'!$U$2:$U$5000,MATCH($I16,'Accounting & Mapping Type'!$T$2:$T$5000,0)),"")),""))) | L16: =IF($J16="N/A","DNP",IF($J16="","",IFERROR(IF(LEN(INDEX('Accounting & Mapping Type'!$V$2:$V$5000,MATCH($J16,'Accounting & Mapping Type'!$T$2:$T$5000,0)))>0,INDEX('Accounting & Mapping Type'!$V$2:$V$5000,MATCH($J16,'Accounting & Mapping Type'!$T$2:$T$5000,0)),IF(LEN(INDEX('Accounting & Mapping Type'!$U$2:$U$5000,MATCH($J16,'Accounting & Mapping Type'!$T$2:$T$5000,0)))>0,INDEX('Accounting & Mapping Type'!$U$2:$U$5000,MATCH($J16,'Accounting & Mapping Type'!$T$2:$T$5000,0)),"")),"")))
I17: =IF($D17="2-Line BTB Offset","N/A","") | J17: =IF($D17="2-Line BTB Bank","N/A","") | K17: =IF($I17="N/A","DNP",IF($I17="","",IFERROR(IF(LEN(INDEX('Accounting & Mapping Type'!$W$2:$W$5000,MATCH($I17,'Accounting & Mapping Type'!$T$2:$T$5000,0)))>0,INDEX('Accounting & Mapping Type'!$W$2:$W$5000,MATCH($I17,'Accounting & Mapping Type'!$T$2:$T$5000,0)),IF(LEN(INDEX('Accounting & Mapping Type'!$U$2:$U$5000,MATCH($I17,'Accounting & Mapping Type'!$T$2:$T$5000,0)))>0,INDEX('Accounting & Mapping Type'!$U$2:$U$5000,MATCH($I17,'Accounting & Mapping Type'!$T$2:$T$5000,0)),"")),""))) | L17: =IF($J17="N/A","DNP",IF($J17="","",IFERROR(IF(LEN(INDEX('Accounting & Mapping Type'!$V$2:$V$5000,MATCH($J17,'Accounting & Mapping Type'!$T$2:$T$5000,0)))>0,INDEX('Accounting & Mapping Type'!$V$2:$V$5000,MATCH($J17,'Accounting & Mapping Type'!$T$2:$T$5000,0)),IF(LEN(INDEX('Accounting & Mapping Type'!$U$2:$U$5000,MATCH($J17,'Accounting & Mapping Type'!$T$2:$T$5000,0)))>0,INDEX('Accounting & Mapping Type'!$U$2:$U$5000,MATCH($J17,'Accounting & Mapping Type'!$T$2:$T$5000,0)),"")),"")))
B18: Move flow code, budget codes (both PET and balance offset) together | I18: =IF($D18="2-Line BTB Offset","N/A","") | J18: =IF($D18="2-Line BTB Bank","N/A","") | K18: =IF($I18="N/A","DNP",IF($I18="","",IFERROR(IF(LEN(INDEX('Accounting & Mapping Type'!$W$2:$W$5000,MATCH($I18,'Accounting & Mapping Type'!$T$2:$T$5000,0)))>0,INDEX('Accounting & Mapping Type'!$W$2:$W$5000,MATCH($I18,'Accounting & Mapping Type'!$T$2:$T$5000,0)),IF(LEN(INDEX('Accounting & Mapping Type'!$U$2:$U$5000,MATCH($I18,'Accounting & Mapping Type'!$T$2:$T$5000,0)))>0,INDEX('Accounting & Mapping Type'!$U$2:$U$5000,MATCH($I18,'Accounting & Mapping Type'!$T$2:$T$5000,0)),"")),""))) | L18: =IF($J18="N/A","DNP",IF($J18="","",IFERROR(IF(LEN(INDEX('Accounting & Mapping Type'!$V$2:$V$5000,MATCH($J18,'Accounting & Mapping Type'!$T$2:$T$5000,0)))>0,INDEX('Accounting & Mapping Type'!$V$2:$V$5000,MATCH($J18,'Accounting & Mapping Type'!$T$2:$T$5000,0)),IF(LEN(INDEX('Accounting & Mapping Type'!$U$2:$U$5000,MATCH($J18,'Accounting & Mapping Type'!$T$2:$T$5000,0)))>0,INDEX('Accounting & Mapping Type'!$U$2:$U$5000,MATCH($J18,'Accounting & Mapping Type'!$T$2:$T$5000,0)),"")),"")))
B19: Direction on 2 and 4 line, remove for other types | I19: =IF($D19="2-Line BTB Offset","N/A","") | J19: =IF($D19="2-Line BTB Bank","N/A","") | K19: =IF($I19="N/A","DNP",IF($I19="","",IFERROR(IF(LEN(INDEX('Accounting & Mapping Type'!$W$2:$W$5000,MATCH($I19,'Accounting & Mapping Type'!$T$2:$T$5000,0)))>0,INDEX('Accounting & Mapping Type'!$W$2:$W$5000,MATCH($I19,'Accounting & Mapping Type'!$T$2:$T$5000,0)),IF(LEN(INDEX('Accounting & Mapping Type'!$U$2:$U$5000,MATCH($I19,'Accounting & Mapping Type'!$T$2:$T$5000,0)))>0,INDEX('Accounting & Mapping Type'!$U$2:$U$5000,MATCH($I19,'Accounting & Mapping Type'!$T$2:$T$5000,0)),"")),""))) | L19: =IF($J19="N/A","DNP",IF($J19="","",IFERROR(IF(LEN(INDEX('Accounting & Mapping Type'!$V$2:$V$5000,MATCH($J19,'Accounting & Mapping Type'!$T$2:$T$5000,0)))>0,INDEX('Accounting & Mapping Type'!$V$2:$V$5000,MATCH($J19,'Accounting & Mapping Type'!$T$2:$T$5000,0)),IF(LEN(INDEX('Accounting & Mapping Type'!$U$2:$U$5000,MATCH($J19,'Accounting & Mapping Type'!$T$2:$T$5000,0)))>0,INDEX('Accounting & Mapping Type'!$U$2:$U$5000,MATCH($J19,'Accounting & Mapping Type'!$T$2:$T$5000,0)),"")),"")))
B20: Bal budget code | I20: =IF($D20="2-Line BTB Offset","N/A","") | J20: =IF($D20="2-Line BTB Bank","N/A","") | K20: =IF($I20="N/A","DNP",IF($I20="","",IFERROR(IF(LEN(INDEX('Accounting & Mapping Type'!$W$2:$W$5000,MATCH($I20,'Accounting & Mapping Type'!$T$2:$T$5000,0)))>0,INDEX('Accounting & Mapping Type'!$W$2:$W$5000,MATCH($I20,'Accounting & Mapping Type'!$T$2:$T$5000,0)),IF(LEN(INDEX('Accounting & Mapping Type'!$U$2:$U$5000,MATCH($I20,'Accounting & Mapping Type'!$T$2:$T$5000,0)))>0,INDEX('Accounting & Mapping Type'!$U$2:$U$5000,MATCH($I20,'Accounting & Mapping Type'!$T$2:$T$5000,0)),"")),""))) | L20: =IF($J20="N/A","DNP",IF($J20="","",IFERROR(IF(LEN(INDEX('Accounting & Mapping Type'!$V$2:$V$5000,MATCH($J20,'Accounting & Mapping Type'!$T$2:$T$5000,0)))>0,INDEX('Accounting & Mapping Type'!$V$2:$V$5000,MATCH($J20,'Accounting & Mapping Type'!$T$2:$T$5000,0)),IF(LEN(INDEX('Accounting & Mapping Type'!$U$2:$U$5000,MATCH($J20,'Accounting & Mapping Type'!$T$2:$T$5000,0)))>0,INDEX('Accounting & Mapping Type'!$U$2:$U$5000,MATCH($J20,'Accounting & Mapping Type'!$T$2:$T$5000,0)),"")),"")))
I21: =IF($D21="2-Line BTB Offset","N/A","") | J21: =IF($D21="2-Line BTB Bank","N/A","") | K21: =IF($I21="N/A","DNP",IF($I21="","",IFERROR(IF(LEN(INDEX('Accounting & Mapping Type'!$W$2:$W$5000,MATCH($I21,'Accounting & Mapping Type'!$T$2:$T$5000,0)))>0,INDEX('Accounting & Mapping Type'!$W$2:$W$5000,MATCH($I21,'Accounting & Mapping Type'!$T$2:$T$5000,0)),IF(LEN(INDEX('Accounting & Mapping Type'!$U$2:$U$5000,MATCH($I21,'Accounting & Mapping Type'!$T$2:$T$5000,0)))>0,INDEX('Accounting & Mapping Type'!$U$2:$U$5000,MATCH($I21,'Accounting & Mapping Type'!$T$2:$T$5000,0)),"")),""))) | L21: =IF($J21="N/A","DNP",IF($J21="","",IFERROR(IF(LEN(INDEX('Accounting & Mapping Type'!$V$2:$V$5000,MATCH($J21,'Accounting & Mapping Type'!$T$2:$T$5000,0)))>0,INDEX('Accounting & Mapping Type'!$V$2:$V$5000,MATCH($J21,'Accounting & Mapping Type'!$T$2:$T$5000,0)),IF(LEN(INDEX('Accounting & Mapping Type'!$U$2:$U$5000,MATCH($J21,'Accounting & Mapping Type'!$T$2:$T$5000,0)))>0,INDEX('Accounting & Mapping Type'!$U$2:$U$5000,MATCH($J21,'Accounting & Mapping Type'!$T$2:$T$5000,0)),"")),"")))
B22: Receipts flow needs budget code | I22: =IF($D22="2-Line BTB Offset","N/A","") | J22: =IF($D22="2-Line BTB Bank","N/A","") | K22: =IF($I22="N/A","DNP",IF($I22="","",IFERROR(IF(LEN(INDEX('Accounting & Mapping Type'!$W$2:$W$5000,MATCH($I22,'Accounting & Mapping Type'!$T$2:$T$5000,0)))>0,INDEX('Accounting & Mapping Type'!$W$2:$W$5000,MATCH($I22,'Accounting & Mapping Type'!$T$2:$T$5000,0)),IF(LEN(INDEX('Accounting & Mapping Type'!$U$2:$U$5000,MATCH($I22,'Accounting & Mapping Type'!$T$2:$T$5000,0)))>0,INDEX('Accounting & Mapping Type'!$U$2:$U$5000,MATCH($I22,'Accounting & Mapping Type'!$T$2:$T$5000,0)),"")),""))) | L22: =IF($J22="N/A","DNP",IF($J22="","",IFERROR(IF(LEN(INDEX('Accounting & Mapping Type'!$V$2:$V$5000,MATCH($J22,'Accounting & Mapping Type'!$T$2:$T$5000,0)))>0,INDEX('Accounting & Mapping Type'!$V$2:$V$5000,MATCH($J22,'Accounting & Mapping Type'!$T$2:$T$5000,0)),IF(LEN(INDEX('Accounting & Mapping Type'!$U$2:$U$5000,MATCH($J22,'Accounting & Mapping Type'!$T$2:$T$5000,0)))>0,INDEX('Accounting & Mapping Type'!$U$2:$U$5000,MATCH($J22,'Accounting & Mapping Type'!$T$2:$T$5000,0)),"")),"")))
I23: =IF($D23="2-Line BTB Offset","N/A","") | J23: =IF($D23="2-Line BTB Bank","N/A","") | K23: =IF($I23="N/A","DNP",IF($I23="","",IFERROR(IF(LEN(INDEX('Accounting & Mapping Type'!$W$2:$W$5000,MATCH($I23,'Accounting & Mapping Type'!$T$2:$T$5000,0)))>0,INDEX('Accounting & Mapping Type'!$W$2:$W$5000,MATCH($I23,'Accounting & Mapping Type'!$T$2:$T$5000,0)),IF(LEN(INDEX('Accounting & Mapping Type'!$U$2:$U$5000,MATCH($I23,'Accounting & Mapping Type'!$T$2:$T$5000,0)))>0,INDEX('Accounting & Mapping Type'!$U$2:$U$5000,MATCH($I23,'Accounting & Mapping Type'!$T$2:$T$5000,0)),"")),""))) | L23: =IF($J23="N/A","DNP",IF($J23="","",IFERROR(IF(LEN(INDEX('Accounting & Mapping Type'!$V$2:$V$5000,MATCH($J23,'Accounting & Mapping Type'!$T$2:$T$5000,0)))>0,INDEX('Accounting & Mapping Type'!$V$2:$V$5000,MATCH($J23,'Accounting & Mapping Type'!$T$2:$T$5000,0)),IF(LEN(INDEX('Accounting & Mapping Type'!$U$2:$U$5000,MATCH($J23,'Accounting & Mapping Type'!$T$2:$T$5000,0)))>0,INDEX('Accounting & Mapping Type'!$U$2:$U$5000,MATCH($J23,'Accounting & Mapping Type'!$T$2:$T$5000,0)),"")),"")))
B24: Receiving bank is a credit | I24: =IF($D24="2-Line BTB Offset","N/A","") | J24: =IF($D24="2-Line BTB Bank","N/A","") | K24: =IF($I24="N/A","DNP",IF($I24="","",IFERROR(IF(LEN(INDEX('Accounting & Mapping Type'!$W$2:$W$5000,MATCH($I24,'Accounting & Mapping Type'!$T$2:$T$5000,0)))>0,INDEX('Accounting & Mapping Type'!$W$2:$W$5000,MATCH($I24,'Accounting & Mapping Type'!$T$2:$T$5000,0)),IF(LEN(INDEX('Accounting & Mapping Type'!$U$2:$U$5000,MATCH($I24,'Accounting & Mapping Type'!$T$2:$T$5000,0)))>0,INDEX('Accounting & Mapping Type'!$U$2:$U$5000,MATCH($I24,'Accounting & Mapping Type'!$T$2:$T$5000,0)),"")),""))) | L24: =IF($J24="N/A","DNP",IF($J24="","",IFERROR(IF(LEN(INDEX('Accounting & Mapping Type'!$V$2:$V$5000,MATCH($J24,'Accounting & Mapping Type'!$T$2:$T$5000,0)))>0,INDEX('Accounting & Mapping Type'!$V$2:$V$5000,MATCH($J24,'Accounting & Mapping Type'!$T$2:$T$5000,0)),IF(LEN(INDEX('Accounting & Mapping Type'!$U$2:$U$5000,MATCH($J24,'Accounting & Mapping Type'!$T$2:$T$5000,0)))>0,INDEX('Accounting & Mapping Type'!$U$2:$U$5000,MATCH($J24,'Accounting & Mapping Type'!$T$2:$T$5000,0)),"")),"")))
I25: =IF($D25="2-Line BTB Offset","N/A","") | J25: =IF($D25="2-Line BTB Bank","N/A","") | K25: =IF($I25="N/A","DNP",IF($I25="","",IFERROR(IF(LEN(INDEX('Accounting & Mapping Type'!$W$2:$W$5000,MATCH($I25,'Accounting & Mapping Type'!$T$2:$T$5000,0)))>0,INDEX('Accounting & Mapping Type'!$W$2:$W$5000,MATCH($I25,'Accounting & Mapping Type'!$T$2:$T$5000,0)),IF(LEN(INDEX('Accounting & Mapping Type'!$U$2:$U$5000,MATCH($I25,'Accounting & Mapping Type'!$T$2:$T$5000,0)))>0,INDEX('Accounting & Mapping Type'!$U$2:$U$5000,MATCH($I25,'Accounting & Mapping Type'!$T$2:$T$5000,0)),"")),""))) | L25: =IF($J25="N/A","DNP",IF($J25="","",IFERROR(IF(LEN(INDEX('Accounting & Mapping Type'!$V$2:$V$5000,MATCH($J25,'Accounting & Mapping Type'!$T$2:$T$5000,0)))>0,INDEX('Accounting & Mapping Type'!$V$2:$V$5000,MATCH($J25,'Accounting & Mapping Type'!$T$2:$T$5000,0)),IF(LEN(INDEX('Accounting & Mapping Type'!$U$2:$U$5000,MATCH($J25,'Accounting & Mapping Type'!$T$2:$T$5000,0)))>0,INDEX('Accounting & Mapping Type'!$U$2:$U$5000,MATCH($J25,'Accounting & Mapping Type'!$T$2:$T$5000,0)),"")),"")))
B26: Confirm budget code is included in the formula (needed for offset formulas in Kyriba, most likely bank as well) | I26: =IF($D26="2-Line BTB Offset","N/A","") | J26: =IF($D26="2-Line BTB Bank","N/A","") | K26: =IF($I26="N/A","DNP",IF($I26="","",IFERROR(IF(LEN(INDEX('Accounting & Mapping Type'!$W$2:$W$5000,MATCH($I26,'Accounting & Mapping Type'!$T$2:$T$5000,0)))>0,INDEX('Accounting & Mapping Type'!$W$2:$W$5000,MATCH($I26,'Accounting & Mapping Type'!$T$2:$T$5000,0)),IF(LEN(INDEX('Accounting & Mapping Type'!$U$2:$U$5000,MATCH($I26,'Accounting & Mapping Type'!$T$2:$T$5000,0)))>0,INDEX('Accounting & Mapping Type'!$U$2:$U$5000,MATCH($I26,'Accounting & Mapping Type'!$T$2:$T$5000,0)),"")),""))) | L26: =IF($J26="N/A","DNP",IF($J26="","",IFERROR(IF(LEN(INDEX('Accounting & Mapping Type'!$V$2:$V$5000,MATCH($J26,'Accounting & Mapping Type'!$T$2:$T$5000,0)))>0,INDEX('Accounting & Mapping Type'!$V$2:$V$5000,MATCH($J26,'Accounting & Mapping Type'!$T$2:$T$5000,0)),IF(LEN(INDEX('Accounting & Mapping Type'!$U$2:$U$5000,MATCH($J26,'Accounting & Mapping Type'!$T$2:$T$5000,0)))>0,INDEX('Accounting & Mapping Type'!$U$2:$U$5000,MATCH($J26,'Accounting & Mapping Type'!$T$2:$T$5000,0)),"")),"")))
I27: =IF($D27="2-Line BTB Offset","N/A","") | J27: =IF($D27="2-Line BTB Bank","N/A","") | K27: =IF($I27="N/A","DNP",IF($I27="","",IFERROR(IF(LEN(INDEX('Accounting & Mapping Type'!$W$2:$W$5000,MATCH($I27,'Accounting & Mapping Type'!$T$2:$T$5000,0)))>0,INDEX('Accounting & Mapping Type'!$W$2:$W$5000,MATCH($I27,'Accounting & Mapping Type'!$T$2:$T$5000,0)),IF(LEN(INDEX('Accounting & Mapping Type'!$U$2:$U$5000,MATCH($I27,'Accounting & Mapping Type'!$T$2:$T$5000,0)))>0,INDEX('Accounting & Mapping Type'!$U$2:$U$5000,MATCH($I27,'Accounting & Mapping Type'!$T$2:$T$5000,0)),"")),""))) | L27: =IF($J27="N/A","DNP",IF($J27="","",IFERROR(IF(LEN(INDEX('Accounting & Mapping Type'!$V$2:$V$5000,MATCH($J27,'Accounting & Mapping Type'!$T$2:$T$5000,0)))>0,INDEX('Accounting & Mapping Type'!$V$2:$V$5000,MATCH($J27,'Accounting & Mapping Type'!$T$2:$T$5000,0)),IF(LEN(INDEX('Accounting & Mapping Type'!$U$2:$U$5000,MATCH($J27,'Accounting & Mapping Type'!$T$2:$T$5000,0)))>0,INDEX('Accounting & Mapping Type'!$U$2:$U$5000,MATCH($J27,'Accounting & Mapping Type'!$T$2:$T$5000,0)),"")),"")))
I28: =IF($D28="2-Line BTB Offset","N/A","") | J28: =IF($D28="2-Line BTB Bank","N/A","") | K28: =IF($I28="N/A","DNP",IF($I28="","",IFERROR(IF(LEN(INDEX('Accounting & Mapping Type'!$W$2:$W$5000,MATCH($I28,'Accounting & Mapping Type'!$T$2:$T$5000,0)))>0,INDEX('Accounting & Mapping Type'!$W$2:$W$5000,MATCH($I28,'Accounting & Mapping Type'!$T$2:$T$5000,0)),IF(LEN(INDEX('Accounting & Mapping Type'!$U$2:$U$5000,MATCH($I28,'Accounting & Mapping Type'!$T$2:$T$5000,0)))>0,INDEX('Accounting & Mapping Type'!$U$2:$U$5000,MATCH($I28,'Accounting & Mapping Type'!$T$2:$T$5000,0)),"")),""))) | L28: =IF($J28="N/A","DNP",IF($J28="","",IFERROR(IF(LEN(INDEX('Accounting & Mapping Type'!$V$2:$V$5000,MATCH($J28,'Accounting & Mapping Type'!$T$2:$T$5000,0)))>0,INDEX('Accounting & Mapping Type'!$V$2:$V$5000,MATCH($J28,'Accounting & Mapping Type'!$T$2:$T$5000,0)),IF(LEN(INDEX('Accounting & Mapping Type'!$U$2:$U$5000,MATCH($J28,'Accounting & Mapping Type'!$T$2:$T$5000,0)))>0,INDEX('Accounting & Mapping Type'!$U$2:$U$5000,MATCH($J28,'Accounting & Mapping Type'!$T$2:$T$5000,0)),"")),"")))
B29: Isolate/restrict drop downs | I29: =IF($D29="2-Line BTB Offset","N/A","") | J29: =IF($D29="2-Line BTB Bank","N/A","") | K29: =IF($I29="N/A","DNP",IF($I29="","",IFERROR(IF(LEN(INDEX('Accounting & Mapping Type'!$W$2:$W$5000,MATCH($I29,'Accounting & Mapping Type'!$T$2:$T$5000,0)))>0,INDEX('Accounting & Mapping Type'!$W$2:$W$5000,MATCH($I29,'Accounting & Mapping Type'!$T$2:$T$5000,0)),IF(LEN(INDEX('Accounting & Mapping Type'!$U$2:$U$5000,MATCH($I29,'Accounting & Mapping Type'!$T$2:$T$5000,0)))>0,INDEX('Accounting & Mapping Type'!$U$2:$U$5000,MATCH($I29,'Accounting & Mapping Type'!$T$2:$T$5000,0)),"")),""))) | L29: =IF($J29="N/A","DNP",IF($J29="","",IFERROR(IF(LEN(INDEX('Accounting & Mapping Type'!$V$2:$V$5000,MATCH($J29,'Accounting & Mapping Type'!$T$2:$T$5000,0)))>0,INDEX('Accounting & Mapping Type'!$V$2:$V$5000,MATCH($J29,'Accounting & Mapping Type'!$T$2:$T$5000,0)),IF(LEN(INDEX('Accounting & Mapping Type'!$U$2:$U$5000,MATCH($J29,'Accounting & Mapping Type'!$T$2:$T$5000,0)))>0,INDEX('Accounting & Mapping Type'!$U$2:$U$5000,MATCH($J29,'Accounting & Mapping Type'!$T$2:$T$5000,0)),"")),"")))
B30: If accounting type is balance, mapping table is balance | I30: =IF($D30="2-Line BTB Offset","N/A","") | J30: =IF($D30="2-Line BTB Bank","N/A","") | K30: =IF($I30="N/A","DNP",IF($I30="","",IFERROR(IF(LEN(INDEX('Accounting & Mapping Type'!$W$2:$W$5000,MATCH($I30,'Accounting & Mapping Type'!$T$2:$T$5000,0)))>0,INDEX('Accounting & Mapping Type'!$W$2:$W$5000,MATCH($I30,'Accounting & Mapping Type'!$T$2:$T$5000,0)),IF(LEN(INDEX('Accounting & Mapping Type'!$U$2:$U$5000,MATCH($I30,'Accounting & Mapping Type'!$T$2:$T$5000,0)))>0,INDEX('Accounting & Mapping Type'!$U$2:$U$5000,MATCH($I30,'Accounting & Mapping Type'!$T$2:$T$5000,0)),"")),""))) | L30: =IF($J30="N/A","DNP",IF($J30="","",IFERROR(IF(LEN(INDEX('Accounting & Mapping Type'!$V$2:$V$5000,MATCH($J30,'Accounting & Mapping Type'!$T$2:$T$5000,0)))>0,INDEX('Accounting & Mapping Type'!$V$2:$V$5000,MATCH($J30,'Accounting & Mapping Type'!$T$2:$T$5000,0)),IF(LEN(INDEX('Accounting & Mapping Type'!$U$2:$U$5000,MATCH($J30,'Accounting & Mapping Type'!$T$2:$T$5000,0)))>0,INDEX('Accounting & Mapping Type'!$U$2:$U$5000,MATCH($J30,'Accounting & Mapping Type'!$T$2:$T$5000,0)),"")),"")))
B31: If 2, 4, receipts, external only option is bank or offset | I31: =IF($D31="2-Line BTB Offset","N/A","") | J31: =IF($D31="2-Line BTB Bank","N/A","") | K31: =IF($I31="N/A","DNP",IF($I31="","",IFERROR(IF(LEN(INDEX('Accounting & Mapping Type'!$W$2:$W$5000,MATCH($I31,'Accounting & Mapping Type'!$T$2:$T$5000,0)))>0,INDEX('Accounting & Mapping Type'!$W$2:$W$5000,MATCH($I31,'Accounting & Mapping Type'!$T$2:$T$5000,0)),IF(LEN(INDEX('Accounting & Mapping Type'!$U$2:$U$5000,MATCH($I31,'Accounting & Mapping Type'!$T$2:$T$5000,0)))>0,INDEX('Accounting & Mapping Type'!$U$2:$U$5000,MATCH($I31,'Accounting & Mapping Type'!$T$2:$T$5000,0)),"")),""))) | L31: =IF($J31="N/A","DNP",IF($J31="","",IFERROR(IF(LEN(INDEX('Accounting & Mapping Type'!$V$2:$V$5000,MATCH($J31,'Accounting & Mapping Type'!$T$2:$T$5000,0)))>0,INDEX('Accounting & Mapping Type'!$V$2:$V$5000,MATCH($J31,'Accounting & Mapping Type'!$T$2:$T$5000,0)),IF(LEN(INDEX('Accounting & Mapping Type'!$U$2:$U$5000,MATCH($J31,'Accounting & Mapping Type'!$T$2:$T$5000,0)))>0,INDEX('Accounting & Mapping Type'!$U$2:$U$5000,MATCH($J31,'Accounting & Mapping Type'!$T$2:$T$5000,0)),"")),"")))
I32: =IF($D32="2-Line BTB Offset","N/A","") | J32: =IF($D32="2-Line BTB Bank","N/A","") | K32: =IF($I32="N/A","DNP",IF($I32="","",IFERROR(IF(LEN(INDEX('Accounting & Mapping Type'!$W$2:$W$5000,MATCH($I32,'Accounting & Mapping Type'!$T$2:$T$5000,0)))>0,INDEX('Accounting & Mapping Type'!$W$2:$W$5000,MATCH($I32,'Accounting & Mapping Type'!$T$2:$T$5000,0)),IF(LEN(INDEX('Accounting & Mapping Type'!$U$2:$U$5000,MATCH($I32,'Accounting & Mapping Type'!$T$2:$T$5000,0)))>0,INDEX('Accounting & Mapping Type'!$U$2:$U$5000,MATCH($I32,'Accounting & Mapping Type'!$T$2:$T$5000,0)),"")),""))) | L32: =IF($J32="N/A","DNP",IF($J32="","",IFERROR(IF(LEN(INDEX('Accounting & Mapping Type'!$V$2:$V$5000,MATCH($J32,'Accounting & Mapping Type'!$T$2:$T$5000,0)))>0,INDEX('Accounting & Mapping Type'!$V$2:$V$5000,MATCH($J32,'Accounting & Mapping Type'!$T$2:$T$5000,0)),IF(LEN(INDEX('Accounting & Mapping Type'!$U$2:$U$5000,MATCH($J32,'Accounting & Mapping Type'!$T$2:$T$5000,0)))>0,INDEX('Accounting & Mapping Type'!$U$2:$U$5000,MATCH($J32,'Accounting & Mapping Type'!$T$2:$T$5000,0)),"")),"")))
I33: =IF($D33="2-Line BTB Offset","N/A","") | J33: =IF($D33="2-Line BTB Bank","N/A","") | K33: =IF($I33="N/A","DNP",IF($I33="","",IFERROR(IF(LEN(INDEX('Accounting & Mapping Type'!$W$2:$W$5000,MATCH($I33,'Accounting & Mapping Type'!$T$2:$T$5000,0)))>0,INDEX('Accounting & Mapping Type'!$W$2:$W$5000,MATCH($I33,'Accounting & Mapping Type'!$T$2:$T$5000,0)),IF(LEN(INDEX('Accounting & Mapping Type'!$U$2:$U$5000,MATCH($I33,'Accounting & Mapping Type'!$T$2:$T$5000,0)))>0,INDEX('Accounting & Mapping Type'!$U$2:$U$5000,MATCH($I33,'Accounting & Mapping Type'!$T$2:$T$5000,0)),"")),""))) | L33: =IF($J33="N/A","DNP",IF($J33="","",IFERROR(IF(LEN(INDEX('Accounting & Mapping Type'!$V$2:$V$5000,MATCH($J33,'Accounting & Mapping Type'!$T$2:$T$5000,0)))>0,INDEX('Accounting & Mapping Type'!$V$2:$V$5000,MATCH($J33,'Accounting & Mapping Type'!$T$2:$T$5000,0)),IF(LEN(INDEX('Accounting & Mapping Type'!$U$2:$U$5000,MATCH($J33,'Accounting & Mapping Type'!$T$2:$T$5000,0)))>0,INDEX('Accounting & Mapping Type'!$U$2:$U$5000,MATCH($J33,'Accounting & Mapping Type'!$T$2:$T$5000,0)),"")),"")))
I34: =IF($D34="2-Line BTB Offset","N/A","") | J34: =IF($D34="2-Line BTB Bank","N/A","") | K34: =IF($I34="N/A","DNP",IF($I34="","",IFERROR(IF(LEN(INDEX('Accounting & Mapping Type'!$W$2:$W$5000,MATCH($I34,'Accounting & Mapping Type'!$T$2:$T$5000,0)))>0,INDEX('Accounting & Mapping Type'!$W$2:$W$5000,MATCH($I34,'Accounting & Mapping Type'!$T$2:$T$5000,0)),IF(LEN(INDEX('Accounting & Mapping Type'!$U$2:$U$5000,MATCH($I34,'Accounting & Mapping Type'!$T$2:$T$5000,0)))>0,INDEX('Accounting & Mapping Type'!$U$2:$U$5000,MATCH($I34,'Accounting & Mapping Type'!$T$2:$T$5000,0)),"")),""))) | L34: =IF($J34="N/A","DNP",IF($J34="","",IFERROR(IF(LEN(INDEX('Accounting & Mapping Type'!$V$2:$V$5000,MATCH($J34,'Accounting & Mapping Type'!$T$2:$T$5000,0)))>0,INDEX('Accounting & Mapping Type'!$V$2:$V$5000,MATCH($J34,'Accounting & Mapping Type'!$T$2:$T$5000,0)),IF(LEN(INDEX('Accounting & Mapping Type'!$U$2:$U$5000,MATCH($J34,'Accounting & Mapping Type'!$T$2:$T$5000,0)))>0,INDEX('Accounting & Mapping Type'!$U$2:$U$5000,MATCH($J34,'Accounting & Mapping Type'!$T$2:$T$5000,0)),"")),"")))
I35: =IF($D35="2-Line BTB Offset","N/A","") | J35: =IF($D35="2-Line BTB Bank","N/A","") | K35: =IF($I35="N/A","DNP",IF($I35="","",IFERROR(IF(LEN(INDEX('Accounting & Mapping Type'!$W$2:$W$5000,MATCH($I35,'Accounting & Mapping Type'!$T$2:$T$5000,0)))>0,INDEX('Accounting & Mapping Type'!$W$2:$W$5000,MATCH($I35,'Accounting & Mapping Type'!$T$2:$T$5000,0)),IF(LEN(INDEX('Accounting & Mapping Type'!$U$2:$U$5000,MATCH($I35,'Accounting & Mapping Type'!$T$2:$T$5000,0)))>0,INDEX('Accounting & Mapping Type'!$U$2:$U$5000,MATCH($I35,'Accounting & Mapping Type'!$T$2:$T$5000,0)),"")),""))) | L35: =IF($J35="N/A","DNP",IF($J35="","",IFERROR(IF(LEN(INDEX('Accounting & Mapping Type'!$V$2:$V$5000,MATCH($J35,'Accounting & Mapping Type'!$T$2:$T$5000,0)))>0,INDEX('Accounting & Mapping Type'!$V$2:$V$5000,MATCH($J35,'Accounting & Mapping Type'!$T$2:$T$5000,0)),IF(LEN(INDEX('Accounting & Mapping Type'!$U$2:$U$5000,MATCH($J35,'Accounting & Mapping Type'!$T$2:$T$5000,0)))>0,INDEX('Accounting & Mapping Type'!$U$2:$U$5000,MATCH($J35,'Accounting & Mapping Type'!$T$2:$T$5000,0)),"")),"")))
I36: =IF($D36="2-Line BTB Offset","N/A","") | J36: =IF($D36="2-Line BTB Bank","N/A","") | K36: =IF($I36="N/A","DNP",IF($I36="","",IFERROR(IF(LEN(INDEX('Accounting & Mapping Type'!$W$2:$W$5000,MATCH($I36,'Accounting & Mapping Type'!$T$2:$T$5000,0)))>0,INDEX('Accounting & Mapping Type'!$W$2:$W$5000,MATCH($I36,'Accounting & Mapping Type'!$T$2:$T$5000,0)),IF(LEN(INDEX('Accounting & Mapping Type'!$U$2:$U$5000,MATCH($I36,'Accounting & Mapping Type'!$T$2:$T$5000,0)))>0,INDEX('Accounting & Mapping Type'!$U$2:$U$5000,MATCH($I36,'Accounting & Mapping Type'!$T$2:$T$5000,0)),"")),""))) | L36: =IF($J36="N/A","DNP",IF($J36="","",IFERROR(IF(LEN(INDEX('Accounting & Mapping Type'!$V$2:$V$5000,MATCH($J36,'Accounting & Mapping Type'!$T$2:$T$5000,0)))>0,INDEX('Accounting & Mapping Type'!$V$2:$V$5000,MATCH($J36,'Accounting & Mapping Type'!$T$2:$T$5000,0)),IF(LEN(INDEX('Accounting & Mapping Type'!$U$2:$U$5000,MATCH($J36,'Accounting & Mapping Type'!$T$2:$T$5000,0)))>0,INDEX('Accounting & Mapping Type'!$U$2:$U$5000,MATCH($J36,'Accounting & Mapping Type'!$T$2:$T$5000,0)),"")),"")))
I37: =IF($D37="2-Line BTB Offset","N/A","") | J37: =IF($D37="2-Line BTB Bank","N/A","") | K37: =IF($I37="N/A","DNP",IF($I37="","",IFERROR(IF(LEN(INDEX('Accounting & Mapping Type'!$W$2:$W$5000,MATCH($I37,'Accounting & Mapping Type'!$T$2:$T$5000,0)))>0,INDEX('Accounting & Mapping Type'!$W$2:$W$5000,MATCH($I37,'Accounting & Mapping Type'!$T$2:$T$5000,0)),IF(LEN(INDEX('Accounting & Mapping Type'!$U$2:$U$5000,MATCH($I37,'Accounting & Mapping Type'!$T$2:$T$5000,0)))>0,INDEX('Accounting & Mapping Type'!$U$2:$U$5000,MATCH($I37,'Accounting & Mapping Type'!$T$2:$T$5000,0)),"")),""))) | L37: =IF($J37="N/A","DNP",IF($J37="","",IFERROR(IF(LEN(INDEX('Accounting & Mapping Type'!$V$2:$V$5000,MATCH($J37,'Accounting & Mapping Type'!$T$2:$T$5000,0)))>0,INDEX('Accounting & Mapping Type'!$V$2:$V$5000,MATCH($J37,'Accounting & Mapping Type'!$T$2:$T$5000,0)),IF(LEN(INDEX('Accounting & Mapping Type'!$U$2:$U$5000,MATCH($J37,'Accounting & Mapping Type'!$T$2:$T$5000,0)))>0,INDEX('Accounting & Mapping Type'!$U$2:$U$5000,MATCH($J37,'Accounting & Mapping Type'!$T$2:$T$5000,0)),"")),"")))
I38: =IF($D38="2-Line BTB Offset","N/A","") | J38: =IF($D38="2-Line BTB Bank","N/A","") | K38: =IF($I38="N/A","DNP",IF($I38="","",IFERROR(IF(LEN(INDEX('Accounting & Mapping Type'!$W$2:$W$5000,MATCH($I38,'Accounting & Mapping Type'!$T$2:$T$5000,0)))>0,INDEX('Accounting & Mapping Type'!$W$2:$W$5000,MATCH($I38,'Accounting & Mapping Type'!$T$2:$T$5000,0)),IF(LEN(INDEX('Accounting & Mapping Type'!$U$2:$U$5000,MATCH($I38,'Accounting & Mapping Type'!$T$2:$T$5000,0)))>0,INDEX('Accounting & Mapping Type'!$U$2:$U$5000,MATCH($I38,'Accounting & Mapping Type'!$T$2:$T$5000,0)),"")),""))) | L38: =IF($J38="N/A","DNP",IF($J38="","",IFERROR(IF(LEN(INDEX('Accounting & Mapping Type'!$V$2:$V$5000,MATCH($J38,'Accounting & Mapping Type'!$T$2:$T$5000,0)))>0,INDEX('Accounting & Mapping Type'!$V$2:$V$5000,MATCH($J38,'Accounting & Mapping Type'!$T$2:$T$5000,0)),IF(LEN(INDEX('Accounting & Mapping Type'!$U$2:$U$5000,MATCH($J38,'Accounting & Mapping Type'!$T$2:$T$5000,0)))>0,INDEX('Accounting & Mapping Type'!$U$2:$U$5000,MATCH($J38,'Accounting & Mapping Type'!$T$2:$T$5000,0)),"")),"")))
I39: =IF($D39="2-Line BTB Offset","N/A","") | J39: =IF($D39="2-Line BTB Bank","N/A","") | K39: =IF($I39="N/A","DNP",IF($I39="","",IFERROR(IF(LEN(INDEX('Accounting & Mapping Type'!$W$2:$W$5000,MATCH($I39,'Accounting & Mapping Type'!$T$2:$T$5000,0)))>0,INDEX('Accounting & Mapping Type'!$W$2:$W$5000,MATCH($I39,'Accounting & Mapping Type'!$T$2:$T$5000,0)),IF(LEN(INDEX('Accounting & Mapping Type'!$U$2:$U$5000,MATCH($I39,'Accounting & Mapping Type'!$T$2:$T$5000,0)))>0,INDEX('Accounting & Mapping Type'!$U$2:$U$5000,MATCH($I39,'Accounting & Mapping Type'!$T$2:$T$5000,0)),"")),""))) | L39: =IF($J39="N/A","DNP",IF($J39="","",IFERROR(IF(LEN(INDEX('Accounting & Mapping Type'!$V$2:$V$5000,MATCH($J39,'Accounting & Mapping Type'!$T$2:$T$5000,0)))>0,INDEX('Accounting & Mapping Type'!$V$2:$V$5000,MATCH($J39,'Accounting & Mapping Type'!$T$2:$T$5000,0)),IF(LEN(INDEX('Accounting & Mapping Type'!$U$2:$U$5000,MATCH($J39,'Accounting & Mapping Type'!$T$2:$T$5000,0)))>0,INDEX('Accounting & Mapping Type'!$U$2:$U$5000,MATCH($J39,'Accounting & Mapping Type'!$T$2:$T$5000,0)),"")),"")))
I40: =IF($D40="2-Line BTB Offset","N/A","") | J40: =IF($D40="2-Line BTB Bank","N/A","") | K40: =IF($I40="N/A","DNP",IF($I40="","",IFERROR(IF(LEN(INDEX('Accounting & Mapping Type'!$W$2:$W$5000,MATCH($I40,'Accounting & Mapping Type'!$T$2:$T$5000,0)))>0,INDEX('Accounting & Mapping Type'!$W$2:$W$5000,MATCH($I40,'Accounting & Mapping Type'!$T$2:$T$5000,0)),IF(LEN(INDEX('Accounting & Mapping Type'!$U$2:$U$5000,MATCH($I40,'Accounting & Mapping Type'!$T$2:$T$5000,0)))>0,INDEX('Accounting & Mapping Type'!$U$2:$U$5000,MATCH($I40,'Accounting & Mapping Type'!$T$2:$T$5000,0)),"")),""))) | L40: =IF($J40="N/A","DNP",IF($J40="","",IFERROR(IF(LEN(INDEX('Accounting & Mapping Type'!$V$2:$V$5000,MATCH($J40,'Accounting & Mapping Type'!$T$2:$T$5000,0)))>0,INDEX('Accounting & Mapping Type'!$V$2:$V$5000,MATCH($J40,'Accounting & Mapping Type'!$T$2:$T$5000,0)),IF(LEN(INDEX('Accounting & Mapping Type'!$U$2:$U$5000,MATCH($J40,'Accounting & Mapping Type'!$T$2:$T$5000,0)))>0,INDEX('Accounting & Mapping Type'!$U$2:$U$5000,MATCH($J40,'Accounting & Mapping Type'!$T$2:$T$5000,0)),"")),"")))
...

Sheet BS Rules & Accounting
A1: Mapping Table in Kyriba Under Mapping rule (Formula Do Not Overwrite) | B1: Formula from 'Treasury Ops Input' Tab Column P Must Be Pasted As Values. NO FORMULAS in This Cell | C1: For +BAL_MODCF Only and Receipts & STO (Formula Do Not Overwrite) | D1: Formula Do Not Overwrite | E1: Required for all Offset and Bank Mapping Tables (Formula Do Not Overwrite) | F1: Required for all Offset and Bank Mapping Tables (Formula Do Not Overwrite) | G1: As Needed (Required for Expense Accounts- GL Accounts Between 5000000000-7999999999) (Formula Do Not Overwrite) | H1: As Needed (Required for Revenue Accounts- GL Accounts Between 4000000000-4999999999) (Formula Do Not Overwrite) | I1: As Needed (Required for Intercompany Accounting) (Formula Do Not Overwrite)
A2: Mapping Table | B2: Input Value | C2: Budget Code | D2: Chart of Accounts | E2: GL Account | F2: Long Text | G2: Cost Center | H2: Profit Center | I2: Trading Partner | J2: Created By | K2: Date Created | L2: Rank
D3: =IF(B3<>"","USA_COA","")
D4: =IF(B4<>"","USA_COA","")
D5: =IF(B5<>"","USA_COA","")
D6: =IF(B6<>"","USA_COA","")
D7: =IF(B7<>"","USA_COA","")
D8: =IF(B8<>"","USA_COA","")
D9: =IF(B9<>"","USA_COA","")
D10: =IF(B10<>"","USA_COA","")
D11: =IF(B11<>"","USA_COA","")
D12: =IF(B12<>"","USA_COA","")
D13: =IF(B13<>"","USA_COA","")
D14: =IF(B14<>"","USA_COA","")
... D1001: =IF(B1001<>"","USA_COA","")

Sheet Formuals
A1: ='FCM Input'!D2 -> Accounting Type | B1: ='FCM Input'!G2 -> PET Code or Description | C1: ='FCM Input'!I2 -> DEBIT Account Code (Outgoing) | D1: ='FCM Input'!E2 -> Flow Code | E1: ='FCM Input'!#REF! -> #REF! | F1: ='FCM Input'!F2 -> PET Budget Code | G1: ='FCM Input'!K2 -> Paying GL Account (Outgoing) | H1: ='FCM Input'!M2 -> Long Text | I1: ='FCM Input'!N2 -> Cost center | J1: ='FCM Input'!O2 -> Profit center | K1: ='FCM Input'!P2 -> Trading partner | L1: ='FCM Input'!Q2 -> Description 2 | M1: ='FCM Input'!R2 -> Description 3
A2: =IF('FCM Input'!D3<>"",'FCM Input'!D3,"") -> +BAL_MODCF | D2: =IF(A2="+BAL_MODCF","+BAL","") -> +BAL
A3: =IF('FCM Input'!D4<>"",'FCM Input'!D4,"") -> 2-Line BTB Bank
A4: =IF('FCM Input'!D5<>"",'FCM Input'!D5,"") -> 2-Line BTB Offset
A5: =IF('FCM Input'!D6<>"",'FCM Input'!D6,"") -> 4-Line BTB Bank
A6: =IF('FCM Input'!D7<>"",'FCM Input'!D7,"") -> 4-Line BTB Offset
A7: =IF('FCM Input'!D8<>"",'FCM Input'!D8,"") -> External
A8: =IF('FCM Input'!D9<>"",'FCM Input'!D9,"") -> Receipts
A9: =IF('FCM Input'!D10<>"",'FCM Input'!D10,"")
A10: =IF('FCM Input'!D11<>"",'FCM Input'!D11,"")
A11: =IF('FCM Input'!D12<>"",'FCM Input'!D12,"")
A12: =IF('FCM Input'!D13<>"",'FCM Input'!D13,"")
A13: =IF('FCM Input'!D14<>"",'FCM Input'!D14,"")
A14: =IF('FCM Input'!D15<>"",'FCM Input'!D15,"")
... A1002: =IF('FCM Input'!D1003<>"",'FCM Input'!D1003,"")
